Workbook

Sheet КАПИТАЛ
A1: № | B1: КАПИТАЛ | C1: 46296 | F1: ± % | G1: 46327 | J1: ± % | K1: 46357
C2: Кол-во / заметка | D2: Сумма, ₽ | E2: Комментарий | G2: Кол-во / заметка | H2: Сумма, ₽ | I2: Комментарий | K2: Кол-во / заметка | L2: Сумма, ₽ | M2: Комментарий
B3: ЛИЧНЫЕ (всего) | D3: =D4+D16+D30 | F3: =IF(OR(N(D3)=0,N(H3)=0),"",(H3-D3)/ABS(D3)) | H3: =H4+H16+H30 | J3: =IF(OR(N(H3)=0,N(L3)=0),"",(L3-H3)/ABS(H3)) | L3: =L4+L16+L30
B4: Активы | D4: =SUM(D5:D15) | F4: =IF(OR(N(D4)=0,N(H4)=0),"",(H4-D4)/ABS(D4)) | H4: =SUM(H5:H15) | J4: =IF(OR(N(H4)=0,N(L4)=0),"",(L4-H4)/ABS(H4)) | L4: =SUM(L5:L15)
A5: 1 | B5: Альфа накопительный | F5: =IF(OR(N(D5)=0,N(H5)=0),"",(H5-D5)/ABS(D5)) | J5: =IF(OR(N(H5)=0,N(L5)=0),"",(L5-H5)/ABS(H5))
A6: 2 | B6: Альфа инвестиции | F6: =IF(OR(N(D6)=0,N(H6)=0),"",(H6-D6)/ABS(D6)) | J6: =IF(OR(N(H6)=0,N(L6)=0),"",(L6-H6)/ABS(H6))
A7: 3 | B7: Райф инвестиции | F7: =IF(OR(N(D7)=0,N(H7)=0),"",(H7-D7)/ABS(D7)) | J7: =IF(OR(N(H7)=0,N(L7)=0),"",(L7-H7)/ABS(H7))
A8: 4 | B8: Тинькофф инвестиции | F8: =IF(OR(N(D8)=0,N(H8)=0),"",(H8-D8)/ABS(D8)) | J8: =IF(OR(N(H8)=0,N(L8)=0),"",(L8-H8)/ABS(H8))
A9: 5 | F9: =IF(OR(N(D9)=0,N(H9)=0),"",(H9-D9)/ABS(D9)) | J9: =IF(OR(N(H9)=0,N(L9)=0),"",(L9-H9)/ABS(H9))
A10: 6 | F10: =IF(OR(N(D10)=0,N(H10)=0),"",(H10-D10)/ABS(D10)) | J10: =IF(OR(N(H10)=0,N(L10)=0),"",(L10-H10)/ABS(H10))
A11: 7 | F11: =IF(OR(N(D11)=0,N(H11)=0),"",(H11-D11)/ABS(D11)) | J11: =IF(OR(N(H11)=0,N(L11)=0),"",(L11-H11)/ABS(H11))
A12: 8 | F12: =IF(OR(N(D12)=0,N(H12)=0),"",(H12-D12)/ABS(D12)) | J12: =IF(OR(N(H12)=0,N(L12)=0),"",(L12-H12)/ABS(H12))
A13: 9 | F13: =IF(OR(N(D13)=0,N(H13)=0),"",(H13-D13)/ABS(D13)) | J13: =IF(OR(N(H13)=0,N(L13)=0),"",(L13-H13)/ABS(H13))
A14: 10 | F14: =IF(OR(N(D14)=0,N(H14)=0),"",(H14-D14)/ABS(D14)) | J14: =IF(OR(N(H14)=0,N(L14)=0),"",(L14-H14)/ABS(H14))
A15: 11 | F15: =IF(OR(N(D15)=0,N(H15)=0),"",(H15-D15)/ABS(D15)) | J15: =IF(OR(N(H15)=0,N(L15)=0),"",(L15-H15)/ABS(H15))
B16: Пассивы | D16: =SUM(D17:D29) | F16: =IF(OR(N(D16)=0,N(H16)=0),"",(H16-D16)/ABS(D16)) | H16: =SUM(H17:H29) | J16: =IF(OR(N(H16)=0,N(L16)=0),"",(L16-H16)/ABS(H16)) | L16: =SUM(L17:L29)
A17: 1 | B17: Альфа карта | F17: =IF(OR(N(D17)=0,N(H17)=0),"",(H17-D17)/ABS(D17)) | J17: =IF(OR(N(H17)=0,N(L17)=0),"",(L17-H17)/ABS(H17))
A18: 2 | B18: Доллары | D18: =C18*C33 | F18: =IF(OR(N(D18)=0,N(H18)=0),"",(H18-D18)/ABS(D18)) | H18: =G18*G33 | J18: =IF(OR(N(H18)=0,N(L18)=0),"",(L18-H18)/ABS(H18)) | L18: =K18*K33
A19: 3 | B19: Евро | D19: =C19*C34 | F19: =IF(OR(N(D19)=0,N(H19)=0),"",(H19-D19)/ABS(D19)) | H19: =G19*G34 | J19: =IF(OR(N(H19)=0,N(L19)=0),"",(L19-H19)/ABS(H19)) | L19: =K19*K34
A20: 4 | B20: Товар whoop | F20: =IF(OR(N(D20)=0,N(H20)=0),"",(H20-D20)/ABS(D20)) | J20: =IF(OR(N(H20)=0,N(L20)=0),"",(L20-H20)/ABS(H20))
A21: 5 | B21: ВТС | D21: =C21*C36 | F21: =IF(OR(N(D21)=0,N(H21)=0),"",(H21-D21)/ABS(D21)) | H21: =G21*G36 | J21: =IF(OR(N(H21)=0,N(L21)=0),"",(L21-H21)/ABS(H21)) | L21: =K21*K36
A22: 6 | B22: Продать на Авито | D22: =Авито!C2 | F22: =IF(OR(N(D22)=0,N(H22)=0),"",(H22-D22)/ABS(D22)) | H22: =Авито!F2 | J22: =IF(OR(N(H22)=0,N(L22)=0),"",(L22-H22)/ABS(H22)) | L22: =Авито!I2
A23: 7 | F23: =IF(OR(N(D23)=0,N(H23)=0),"",(H23-D23)/ABS(D23)) | J23: =IF(OR(N(H23)=0,N(L23)=0),"",(L23-H23)/ABS(H23))
A24: 8 | F24: =IF(OR(N(D24)=0,N(H24)=0),"",(H24-D24)/ABS(D24)) | J24: =IF(OR(N(H24)=0,N(L24)=0),"",(L24-H24)/ABS(H24))
A25: 9 | F25: =IF(OR(N(D25)=0,N(H25)=0),"",(H25-D25)/ABS(D25)) | J25: =IF(OR(N(H25)=0,N(L25)=0),"",(L25-H25)/ABS(H25))
A26: 10 | F26: =IF(OR(N(D26)=0,N(H26)=0),"",(H26-D26)/ABS(D26)) | J26: =IF(OR(N(H26)=0,N(L26)=0),"",(L26-H26)/ABS(H26))
A27: 11 | F27: =IF(OR(N(D27)=0,N(H27)=0),"",(H27-D27)/ABS(D27)) | J27: =IF(OR(N(H27)=0,N(L27)=0),"",(L27-H27)/ABS(H27))
A28: 12 | F28: =IF(OR(N(D28)=0,N(H28)=0),"",(H28-D28)/ABS(D28)) | J28: =IF(OR(N(H28)=0,N(L28)=0),"",(L28-H28)/ABS(H28))
A29: 13 | F29: =IF(OR(N(D29)=0,N(H29)=0),"",(H29-D29)/ABS(D29)) | J29: =IF(OR(N(H29)=0,N(L29)=0),"",(L29-H29)/ABS(H29))
B30: Плавающий капитал (с листа) | D30: ='Плавающий капитал'!D3 | F30: =IF(OR(N(D30)=0,N(H30)=0),"",(H30-D30)/ABS(D30)) | H30: ='Плавающий капитал'!H3 | J30: =IF(OR(N(H30)=0,N(L30)=0),"",(L30-H30)/ABS(H30)) | L30: ='Плавающий капитал'!L3
B32: Курсы на 29-е число, 10:00, ₽ | C32: =DATE(YEAR(C$1),MONTH(C$1),MIN(29,DAY(EOMONTH(C$1,0))))+TIME(10,0,0) | F32: ± % | G32: =DATE(YEAR(G$1),MONTH(G$1),MIN(29,DAY(EOMONTH(G$1,0))))+TIME(10,0,0) | J32: ± % | K32: =DATE(YEAR(K$1),MONTH(K$1),MIN(29,DAY(EOMONTH(K$1,0))))+TIME(10,0,0)
B33: Доллар | C33: =IF(OR(C$32="",NOW()<C$32),"",IFERROR(IMPORTXML("https://www.cbr.ru/scripts/XML_daily.asp?date_req="&TEXT(C$32,"dd/mm/yyyy"),"translate(//Valute[CharCode='USD']/Value,',','')")/10000/IMPORTXML("https://www.cbr.ru/scripts/XML_daily.asp?date_req="&TEXT(C$32,"dd/mm/yyyy"),"//Valute[CharCode='USD']/Nominal"),"")) | F33: =IF(OR(N(C33)=0,N(G33)=0),"",(G33-C33)/ABS(C33)) | G33: =IF(OR(G$32="",NOW()<G$32),"",IFERROR(IMPORTXML("https://www.cbr.ru/scripts/XML_daily.asp?date_req="&TEXT(G$32,"dd/mm/yyyy"),"translate(//Valute[CharCode='USD']/Value,',','')")/10000/IMPORTXML("https://www.cbr.ru/scripts/XML_daily.asp?date_req="&TEXT(G$32,"dd/mm/yyyy"),"//Valute[CharCode='USD']/Nominal"),"")) | J33: =IF(OR(N(G33)=0,N(K33)=0),"",(K33-G33)/ABS(G33)) | K33: =IF(OR(K$32="",NOW()<K$32),"",IFERROR(IMPORTXML("https://www.cbr.ru/scripts/XML_daily.asp?date_req="&TEXT(K$32,"dd/mm/yyyy"),"translate(//Valute[CharCode='USD']/Value,',','')")/10000/IMPORTXML("https://www.cbr.ru/scripts/XML_daily.asp?date_req="&TEXT(K$32,"dd/mm/yyyy"),"//Valute[CharCode='USD']/Nominal"),""))
B34: Евро | C34: =IF(OR(C$32="",NOW()<C$32),"",IFERROR(IMPORTXML("https://www.cbr.ru/scripts/XML_daily.asp?date_req="&TEXT(C$32,"dd/mm/yyyy"),"translate(//Valute[CharCode='EUR']/Value,',','')")/10000/IMPORTXML("https://www.cbr.ru/scripts/XML_daily.asp?date_req="&TEXT(C$32,"dd/mm/yyyy"),"//Valute[CharCode='EUR']/Nominal"),"")) | F34: =IF(OR(N(C34)=0,N(G34)=0),"",(G34-C34)/ABS(C34)) | G34: =IF(OR(G$32="",NOW()<G$32),"",IFERROR(IMPORTXML("https://www.cbr.ru/scripts/XML_daily.asp?date_req="&TEXT(G$32,"dd/mm/yyyy"),"translate(//Valute[CharCode='EUR']/Value,',','')")/10000/IMPORTXML("https://www.cbr.ru/scripts/XML_daily.asp?date_req="&TEXT(G$32,"dd/mm/yyyy"),"//Valute[CharCode='EUR']/Nominal"),"")) | J34: =IF(OR(N(G34)=0,N(K34)=0),"",(K34-G34)/ABS(G34)) | K34: =IF(OR(K$32="",NOW()<K$32),"",IFERROR(IMPORTXML("https://www.cbr.ru/scripts/XML_daily.asp?date_req="&TEXT(K$32,"dd/mm/yyyy"),"translate(//Valute[CharCode='EUR']/Value,',','')")/10000/IMPORTXML("https://www.cbr.ru/scripts/XML_daily.asp?date_req="&TEXT(K$32,"dd/mm/yyyy"),"//Valute[CharCode='EUR']/Nominal"),""))
B35: Бат | C35: =IF(OR(C$32="",NOW()<C$32),"",IFERROR(IMPORTXML("https://www.cbr.ru/scripts/XML_daily.asp?date_req="&TEXT(C$32,"dd/mm/yyyy"),"translate(//Valute[CharCode='THB']/Value,',','')")/10000/IMPORTXML("https://www.cbr.ru/scripts/XML_daily.asp?date_req="&TEXT(C$32,"dd/mm/yyyy"),"//Valute[CharCode='THB']/Nominal"),"")) | F35: =IF(OR(N(C35)=0,N(G35)=0),"",(G35-C35)/ABS(C35)) | G35: =IF(OR(G$32="",NOW()<G$32),"",IFERROR(IMPORTXML("https://www.cbr.ru/scripts/XML_daily.asp?date_req="&TEXT(G$32,"dd/mm/yyyy"),"translate(//Valute[CharCode='THB']/Value,',','')")/10000/IMPORTXML("https://www.cbr.ru/scripts/XML_daily.asp?date_req="&TEXT(G$32,"dd/mm/yyyy"),"//Valute[CharCode='THB']/Nominal"),"")) | J35: =IF(OR(N(G35)=0,N(K35)=0),"",(K35-G35)/ABS(G35)) | K35: =IF(OR(K$32="",NOW()<K$32),"",IFERROR(IMPORTXML("https://www.cbr.ru/scripts/XML_daily.asp?date_req="&TEXT(K$32,"dd/mm/yyyy"),"translate(//Valute[CharCode='THB']/Value,',','')")/10000/IMPORTXML("https://www.cbr.ru/scripts/XML_daily.asp?date_req="&TEXT(K$32,"dd/mm/yyyy"),"//Valute[CharCode='THB']/Nominal"),""))
B36: ВТС | C36: =IF(OR(C$32="",NOW()<C$32,N(C33)=0),"",IFERROR(IF(INT(C$32)=TODAY(),GOOGLEFINANCE("CURRENCY:BTCUSD"),INDEX(GOOGLEFINANCE("CURRENCY:BTCUSD","price",C$32),2,2))*C33,"")) | F36: =IF(OR(N(C36)=0,N(G36)=0),"",(G36-C36)/ABS(C36)) | G36: =IF(OR(G$32="",NOW()<G$32,N(G33)=0),"",IFERROR(IF(INT(G$32)=TODAY(),GOOGLEFINANCE("CURRENCY:BTCUSD"),INDEX(GOOGLEFINANCE("CURRENCY:BTCUSD","price",G$32),2,2))*G33,"")) | J36: =IF(OR(N(G36)=0,N(K36)=0),"",(K36-G36)/ABS(G36)) | K36: =IF(OR(K$32="",NOW()<K$32,N(K33)=0),"",IFERROR(IF(INT(K$32)=TODAY(),GOOGLEFINANCE("CURRENCY:BTCUSD"),INDEX(GOOGLEFINANCE("CURRENCY:BTCUSD","price",K$32),2,2))*K33,""))
B37: ETH | C37: =IF(OR(C$32="",NOW()<C$32,N(C33)=0),"",IFERROR(IF(INT(C$32)=TODAY(),GOOGLEFINANCE("CURRENCY:ETHUSD"),INDEX(GOOGLEFINANCE("CURRENCY:ETHUSD","price",C$32),2,2))*C33,"")) | F37: =IF(OR(N(C37)=0,N(G37)=0),"",(G37-C37)/ABS(C37)) | G37: =IF(OR(G$32="",NOW()<G$32,N(G33)=0),"",IFERROR(IF(INT(G$32)=TODAY(),GOOGLEFINANCE("CURRENCY:ETHUSD"),INDEX(GOOGLEFINANCE("CURRENCY:ETHUSD","price",G$32),2,2))*G33,"")) | J37: =IF(OR(N(G37)=0,N(K37)=0),"",(K37-G37)/ABS(G37)) | K37: =IF(OR(K$32="",NOW()<K$32,N(K33)=0),"",IFERROR(IF(INT(K$32)=TODAY(),GOOGLEFINANCE("CURRENCY:ETHUSD"),INDEX(GOOGLEFINANCE("CURRENCY:ETHUSD","price",K$32),2,2))*K33,""))
B39: Светло-жёлтые ячейки — для ввода. Серые и синие — считаются формулами, их не трогать. «± %» — изменение к прошлому месяцу (зелёный — рост, красный — падение), появляется, когда заполнены оба месяца. «Продать на Авито» и «Плавающий капитал» подтягиваются со своих листов. Доллары/Евро/ВТС = кол-во × курс. У каждого месяца своя колонка «Комментарий». Курсы (строки 33–37) подтягиваются сами 29-го числа месяца в 10:00: доллар, евро, бат — ЦБ РФ; BTC, ETH — GOOGLEFINANCE (к USD) × курс доллара ЦБ.

Sheet Плавающий капитал
A1: № | B1: ПЛАВАЮЩИЙ КАПИТАЛ | C1: 46296 | F1: ± % | G1: 46327 | J1: ± % | K1: 46357
C2: Кол-во / заметка | D2: Сумма, ₽ | E2: Комментарий | G2: Кол-во / заметка | H2: Сумма, ₽ | I2: Комментарий | K2: Кол-во / заметка | L2: Сумма, ₽ | M2: Комментарий
B3: Плавающий капитал (всего) | D3: =D4 | F3: =IF(OR(N(D3)=0,N(H3)=0),"",(H3-D3)/ABS(D3)) | H3: =H4 | J3: =IF(OR(N(H3)=0,N(L3)=0),"",(L3-H3)/ABS(H3)) | L3: =L4
B4: Активы | D4: =SUM(D5:D12) | F4: =IF(OR(N(D4)=0,N(H4)=0),"",(H4-D4)/ABS(D4)) | H4: =SUM(H5:H12) | J4: =IF(OR(N(H4)=0,N(L4)=0),"",(L4-H4)/ABS(H4)) | L4: =SUM(L5:L12)
A5: 1 | F5: =IF(OR(N(D5)=0,N(H5)=0),"",(H5-D5)/ABS(D5)) | J5: =IF(OR(N(H5)=0,N(L5)=0),"",(L5-H5)/ABS(H5))
A6: 2 | F6: =IF(OR(N(D6)=0,N(H6)=0),"",(H6-D6)/ABS(D6)) | J6: =IF(OR(N(H6)=0,N(L6)=0),"",(L6-H6)/ABS(H6))
A7: 3 | F7: =IF(OR(N(D7)=0,N(H7)=0),"",(H7-D7)/ABS(D7)) | J7: =IF(OR(N(H7)=0,N(L7)=0),"",(L7-H7)/ABS(H7))
A8: 4 | F8: =IF(OR(N(D8)=0,N(H8)=0),"",(H8-D8)/ABS(D8)) | J8: =IF(OR(N(H8)=0,N(L8)=0),"",(L8-H8)/ABS(H8))
A9: 5 | F9: =IF(OR(N(D9)=0,N(H9)=0),"",(H9-D9)/ABS(D9)) | J9: =IF(OR(N(H9)=0,N(L9)=0),"",(L9-H9)/ABS(H9))
A10: 6 | F10: =IF(OR(N(D10)=0,N(H10)=0),"",(H10-D10)/ABS(D10)) | J10: =IF(OR(N(H10)=0,N(L10)=0),"",(L10-H10)/ABS(H10))
A11: 7 | F11: =IF(OR(N(D11)=0,N(H11)=0),"",(H11-D11)/ABS(D11)) | J11: =IF(OR(N(H11)=0,N(L11)=0),"",(L11-H11)/ABS(H11))
A12: 8 | F12: =IF(OR(N(D12)=0,N(H12)=0),"",(H12-D12)/ABS(D12)) | J12: =IF(OR(N(H12)=0,N(L12)=0),"",(L12-H12)/ABS(H12))
B14: Светло-жёлтые ячейки — для ввода. Серые и синие — считаются формулами, их не трогать. «± %» — изменение к прошлому месяцу (зелёный — рост, красный — падение), появляется, когда заполнены оба месяца. Названия статей вписывай сам в колонку B. Итог попадает в «КАПИТАЛ». У каждого месяца своя колонка «Комментарий».

Sheet Доходы Расходы
A1: № | B1: Статья | C1: 46296 | D1: Комментарий | E1: ± % | F1: 46327 | G1: Комментарий | H1: ± % | I1: 46357 | J1: Комментарий | K1: Итого за период
B2: Доходы — итого за месяц | C2: =SUM(C3:C15) | E2: =IF(OR(N(C2)=0,N(F2)=0),"",(F2-C2)/ABS(C2)) | F2: =SUM(F3:F15) | H2: =IF(OR(N(F2)=0,N(I2)=0),"",(I2-F2)/ABS(F2)) | I2: =SUM(I3:I15) | K2: =SUM(C2,F2,I2)
A3: 1 | B3: Карманные деньги | E3: =IF(OR(N(C3)=0,N(F3)=0),"",(F3-C3)/ABS(C3)) | H3: =IF(OR(N(F3)=0,N(I3)=0),"",(I3-F3)/ABS(F3)) | K3: =SUM(C3,F3,I3)
A4: 2 | B4: Аванс на расходы | E4: =IF(OR(N(C4)=0,N(F4)=0),"",(F4-C4)/ABS(C4)) | H4: =IF(OR(N(F4)=0,N(I4)=0),"",(I4-F4)/ABS(F4)) | K4: =SUM(C4,F4,I4)
A5: 3 | B5: Авито | E5: =IF(OR(N(C5)=0,N(F5)=0),"",(F5-C5)/ABS(C5)) | H5: =IF(OR(N(F5)=0,N(I5)=0),"",(I5-F5)/ABS(F5)) | K5: =SUM(C5,F5,I5)
A6: 4 | B6: Подарки | E6: =IF(OR(N(C6)=0,N(F6)=0),"",(F6-C6)/ABS(C6)) | H6: =IF(OR(N(F6)=0,N(I6)=0),"",(I6-F6)/ABS(F6)) | K6: =SUM(C6,F6,I6)
A7: 5 | B7: Whoop | E7: =IF(OR(N(C7)=0,N(F7)=0),"",(F7-C7)/ABS(C7)) | H7: =IF(OR(N(F7)=0,N(I7)=0),"",(I7-F7)/ABS(F7)) | K7: =SUM(C7,F7,I7)
A8: 6 | B8: Прочие | E8: =IF(OR(N(C8)=0,N(F8)=0),"",(F8-C8)/ABS(C8)) | H8: =IF(OR(N(F8)=0,N(I8)=0),"",(I8-F8)/ABS(F8)) | K8: =SUM(C8,F8,I8)
A9: 7 | E9: =IF(OR(N(C9)=0,N(F9)=0),"",(F9-C9)/ABS(C9)) | H9: =IF(OR(N(F9)=0,N(I9)=0),"",(I9-F9)/ABS(F9)) | K9: =SUM(C9,F9,I9)
A10: 8 | E10: =IF(OR(N(C10)=0,N(F10)=0),"",(F10-C10)/ABS(C10)) | H10: =IF(OR(N(F10)=0,N(I10)=0),"",(I10-F10)/ABS(F10)) | K10: =SUM(C10,F10,I10)
A11: 9 | E11: =IF(OR(N(C11)=0,N(F11)=0),"",(F11-C11)/ABS(C11)) | H11: =IF(OR(N(F11)=0,N(I11)=0),"",(I11-F11)/ABS(F11)) | K11: =SUM(C11,F11,I11)
A12: 10 | E12: =IF(OR(N(C12)=0,N(F12)=0),"",(F12-C12)/ABS(C12)) | H12: =IF(OR(N(F12)=0,N(I12)=0),"",(I12-F12)/ABS(F12)) | K12: =SUM(C12,F12,I12)
A13: 11 | E13: =IF(OR(N(C13)=0,N(F13)=0),"",(F13-C13)/ABS(C13)) | H13: =IF(OR(N(F13)=0,N(I13)=0),"",(I13-F13)/ABS(F13)) | K13: =SUM(C13,F13,I13)
A14: 12 | E14: =IF(OR(N(C14)=0,N(F14)=0),"",(F14-C14)/ABS(C14)) | H14: =IF(OR(N(F14)=0,N(I14)=0),"",(I14-F14)/ABS(F14)) | K14: =SUM(C14,F14,I14)
A15: 13 | E15: =IF(OR(N(C15)=0,N(F15)=0),"",(F15-C15)/ABS(C15)) | H15: =IF(OR(N(F15)=0,N(I15)=0),"",(I15-F15)/ABS(F15)) | K15: =SUM(C15,F15,I15)
B16: Расходы — итого за месяц | C16: =SUM(C17:C29) | E16: =IF(OR(N(C16)=0,N(F16)=0),"",(F16-C16)/ABS(C16)) | F16: =SUM(F17:F29) | H16: =IF(OR(N(F16)=0,N(I16)=0),"",(I16-F16)/ABS(F16)) | I16: =SUM(I17:I29) | K16: =SUM(C16,F16,I16)
A17: 1 | B17: Рестораны | E17: =IF(OR(N(C17)=0,N(F17)=0),"",(F17-C17)/ABS(C17)) | H17: =IF(OR(N(F17)=0,N(I17)=0),"",(I17-F17)/ABS(F17)) | K17: =SUM(C17,F17,I17)
A18: 2 | B18: Интернет покупки | E18: =IF(OR(N(C18)=0,N(F18)=0),"",(F18-C18)/ABS(C18)) | H18: =IF(OR(N(F18)=0,N(I18)=0),"",(I18-F18)/ABS(F18)) | K18: =SUM(C18,F18,I18)
A19: 3 | B19: Подарки | E19: =IF(OR(N(C19)=0,N(F19)=0),"",(F19-C19)/ABS(C19)) | H19: =IF(OR(N(F19)=0,N(I19)=0),"",(I19-F19)/ABS(F19)) | K19: =SUM(C19,F19,I19)
A20: 4 | B20: Одежда | E20: =IF(OR(N(C20)=0,N(F20)=0),"",(F20-C20)/ABS(C20)) | H20: =IF(OR(N(F20)=0,N(I20)=0),"",(I20-F20)/ABS(F20)) | K20: =SUM(C20,F20,I20)
A21: 5 | B21: МТС | E21: =IF(OR(N(C21)=0,N(F21)=0),"",(F21-C21)/ABS(C21)) | H21: =IF(OR(N(F21)=0,N(I21)=0),"",(I21-F21)/ABS(F21)) | K21: =SUM(C21,F21,I21)
A22: 6 | B22: Прочие | E22: =IF(OR(N(C22)=0,N(F22)=0),"",(F22-C22)/ABS(C22)) | H22: =IF(OR(N(F22)=0,N(I22)=0),"",(I22-F22)/ABS(F22)) | K22: =SUM(C22,F22,I22)
A23: 7 | B23: Курс | E23: =IF(OR(N(C23)=0,N(F23)=0),"",(F23-C23)/ABS(C23)) | H23: =IF(OR(N(F23)=0,N(I23)=0),"",(I23-F23)/ABS(F23)) | K23: =SUM(C23,F23,I23)
A24: 8 | E24: =IF(OR(N(C24)=0,N(F24)=0),"",(F24-C24)/ABS(C24)) | H24: =IF(OR(N(F24)=0,N(I24)=0),"",(I24-F24)/ABS(F24)) | K24: =SUM(C24,F24,I24)
A25: 9 | E25: =IF(OR(N(C25)=0,N(F25)=0),"",(F25-C25)/ABS(C25)) | H25: =IF(OR(N(F25)=0,N(I25)=0),"",(I25-F25)/ABS(F25)) | K25: =SUM(C25,F25,I25)
A26: 10 | E26: =IF(OR(N(C26)=0,N(F26)=0),"",(F26-C26)/ABS(C26)) | H26: =IF(OR(N(F26)=0,N(I26)=0),"",(I26-F26)/ABS(F26)) | K26: =SUM(C26,F26,I26)
A27: 11 | E27: =IF(OR(N(C27)=0,N(F27)=0),"",(F27-C27)/ABS(C27)) | H27: =IF(OR(N(F27)=0,N(I27)=0),"",(I27-F27)/ABS(F27)) | K27: =SUM(C27,F27,I27)
A28: 12 | E28: =IF(OR(N(C28)=0,N(F28)=0),"",(F28-C28)/ABS(C28)) | H28: =IF(OR(N(F28)=0,N(I28)=0),"",(I28-F28)/ABS(F28)) | K28: =SUM(C28,F28,I28)
A29: 13 | E29: =IF(OR(N(C29)=0,N(F29)=0),"",(F29-C29)/ABS(C29)) | H29: =IF(OR(N(F29)=0,N(I29)=0),"",(I29-F29)/ABS(F29)) | K29: =SUM(C29,F29,I29)
B30: Расходы 11 — итого за месяц | C30: =SUM(C31:C40) | E30: =IF(OR(N(C30)=0,N(F30)=0),"",(F30-C30)/ABS(C30)) | F30: =SUM(F31:F40) | H30: =IF(OR(N(F30)=0,N(I30)=0),"",(I30-F30)/ABS(F30)) | I30: =SUM(I31:I40) | K30: =SUM(C30,F30,I30)
A31: 1 | E31: =IF(OR(N(C31)=0,N(F31)=0),"",(F31-C31)/ABS(C31)) | H31: =IF(OR(N(F31)=0,N(I31)=0),"",(I31-F31)/ABS(F31)) | K31: =SUM(C31,F31,I31)
A32: 2 | E32: =IF(OR(N(C32)=0,N(F32)=0),"",(F32-C32)/ABS(C32)) | H32: =IF(OR(N(F32)=0,N(I32)=0),"",(I32-F32)/ABS(F32)) | K32: =SUM(C32,F32,I32)
A33: 3 | E33: =IF(OR(N(C33)=0,N(F33)=0),"",(F33-C33)/ABS(C33)) | H33: =IF(OR(N(F33)=0,N(I33)=0),"",(I33-F33)/ABS(F33)) | K33: =SUM(C33,F33,I33)
A34: 4 | E34: =IF(OR(N(C34)=0,N(F34)=0),"",(F34-C34)/ABS(C34)) | H34: =IF(OR(N(F34)=0,N(I34)=0),"",(I34-F34)/ABS(F34)) | K34: =SUM(C34,F34,I34)
A35: 5 | E35: =IF(OR(N(C35)=0,N(F35)=0),"",(F35-C35)/ABS(C35)) | H35: =IF(OR(N(F35)=0,N(I35)=0),"",(I35-F35)/ABS(F35)) | K35: =SUM(C35,F35,I35)
A36: 6 | E36: =IF(OR(N(C36)=0,N(F36)=0),"",(F36-C36)/ABS(C36)) | H36: =IF(OR(N(F36)=0,N(I36)=0),"",(I36-F36)/ABS(F36)) | K36: =SUM(C36,F36,I36)
A37: 7 | E37: =IF(OR(N(C37)=0,N(F37)=0),"",(F37-C37)/ABS(C37)) | H37: =IF(OR(N(F37)=0,N(I37)=0),"",(I37-F37)/ABS(F37)) | K37: =SUM(C37,F37,I37)
A38: 8 | E38: =IF(OR(N(C38)=0,N(F38)=0),"",(F38-C38)/ABS(C38)) | H38: =IF(OR(N(F38)=0,N(I38)=0),"",(I38-F38)/ABS(F38)) | K38: =SUM(C38,F38,I38)
A39: 9 | E39: =IF(OR(N(C39)=0,N(F39)=0),"",(F39-C39)/ABS(C39)) | H39: =IF(OR(N(F39)=0,N(I39)=0),"",(I39-F39)/ABS(F39)) | K39: =SUM(C39,F39,I39)
A40: 10 | E40: =IF(OR(N(C40)=0,N(F40)=0),"",(F40-C40)/ABS(C40)) | H40: =IF(OR(N(F40)=0,N(I40)=0),"",(I40-F40)/ABS(F40)) | K40: =SUM(C40,F40,I40)
...

Sheet Долг
A1: № | B1: Статья | C1: 46296 | D1: Комментарий | E1: ± % | F1: 46327 | G1: Комментарий | H1: ± % | I1: 46357 | J1: Комментарий | K1: Итого за период
B2: Долг — итого за месяц | C2: =SUM(C3:C15) | E2: =IF(OR(N(C2)=0,N(F2)=0),"",(F2-C2)/ABS(C2)) | F2: =SUM(F3:F15) | H2: =IF(OR(N(F2)=0,N(I2)=0),"",(I2-F2)/ABS(F2)) | I2: =SUM(I3:I15) | K2: =SUM(C2,F2,I2)
A3: 1 | B3: Кафе/доставка | E3: =IF(OR(N(C3)=0,N(F3)=0),"",(F3-C3)/ABS(C3)) | H3: =IF(OR(N(F3)=0,N(I3)=0),"",(I3-F3)/ABS(F3)) | K3: =SUM(C3,F3,I3)
A4: 2 | B4: Барбершоп | E4: =IF(OR(N(C4)=0,N(F4)=0),"",(F4-C4)/ABS(C4)) | H4: =IF(OR(N(F4)=0,N(I4)=0),"",(I4-F4)/ABS(F4)) | K4: =SUM(C4,F4,I4)
A5: 3 | B5: Такси | E5: =IF(OR(N(C5)=0,N(F5)=0),"",(F5-C5)/ABS(C5)) | H5: =IF(OR(N(F5)=0,N(I5)=0),"",(I5-F5)/ABS(F5)) | K5: =SUM(C5,F5,I5)
A6: 4 | B6: Озон/уходовые | E6: =IF(OR(N(C6)=0,N(F6)=0),"",(F6-C6)/ABS(C6)) | H6: =IF(OR(N(F6)=0,N(I6)=0),"",(I6-F6)/ABS(F6)) | K6: =SUM(C6,F6,I6)
A7: 5 | B7: Спорт | E7: =IF(OR(N(C7)=0,N(F7)=0),"",(F7-C7)/ABS(C7)) | H7: =IF(OR(N(F7)=0,N(I7)=0),"",(I7-F7)/ABS(F7)) | K7: =SUM(C7,F7,I7)
A8: 6 | B8: Одежда | E8: =IF(OR(N(C8)=0,N(F8)=0),"",(F8-C8)/ABS(C8)) | H8: =IF(OR(N(F8)=0,N(I8)=0),"",(I8-F8)/ABS(F8)) | K8: =SUM(C8,F8,I8)
A9: 7 | B9: Баня | E9: =IF(OR(N(C9)=0,N(F9)=0),"",(F9-C9)/ABS(C9)) | H9: =IF(OR(N(F9)=0,N(I9)=0),"",(I9-F9)/ABS(F9)) | K9: =SUM(C9,F9,I9)
A10: 8 | E10: =IF(OR(N(C10)=0,N(F10)=0),"",(F10-C10)/ABS(C10)) | H10: =IF(OR(N(F10)=0,N(I10)=0),"",(I10-F10)/ABS(F10)) | K10: =SUM(C10,F10,I10)
A11: 9 | E11: =IF(OR(N(C11)=0,N(F11)=0),"",(F11-C11)/ABS(C11)) | H11: =IF(OR(N(F11)=0,N(I11)=0),"",(I11-F11)/ABS(F11)) | K11: =SUM(C11,F11,I11)
A12: 10 | E12: =IF(OR(N(C12)=0,N(F12)=0),"",(F12-C12)/ABS(C12)) | H12: =IF(OR(N(F12)=0,N(I12)=0),"",(I12-F12)/ABS(F12)) | K12: =SUM(C12,F12,I12)
A13: 11 | E13: =IF(OR(N(C13)=0,N(F13)=0),"",(F13-C13)/ABS(C13)) | H13: =IF(OR(N(F13)=0,N(I13)=0),"",(I13-F13)/ABS(F13)) | K13: =SUM(C13,F13,I13)
A14: 12 | E14: =IF(OR(N(C14)=0,N(F14)=0),"",(F14-C14)/ABS(C14)) | H14: =IF(OR(N(F14)=0,N(I14)=0),"",(I14-F14)/ABS(F14)) | K14: =SUM(C14,F14,I14)
A15: 13 | E15: =IF(OR(N(C15)=0,N(F15)=0),"",(F15-C15)/ABS(C15)) | H15: =IF(OR(N(F15)=0,N(I15)=0),"",(I15-F15)/ABS(F15)) | K15: =SUM(C15,F15,I15)
B16: Дали | E16: =IF(OR(N(C16)=0,N(F16)=0),"",(F16-C16)/ABS(C16)) | H16: =IF(OR(N(F16)=0,N(I16)=0),"",(I16-F16)/ABS(F16)) | K16: =SUM(C16,F16,I16)
B17: Итого (Долг − Дали) | C17: =C2-C16 | E17: =IF(OR(N(C17)=0,N(F17)=0),"",(F17-C17)/ABS(C17)) | F17: =F2-F16 | H17: =IF(OR(N(F17)=0,N(I17)=0),"",(I17-F17)/ABS(F17)) | I17: =I2-I16 | K17: =SUM(C17,F17,I17)
B19: Светло-жёлтые ячейки — для ввода. Серые и синие — считаются формулами, их не трогать. «± %» — изменение к прошлому месяцу (зелёный — рост, красный — падение), появляется, когда заполнены оба месяца. У каждого месяца своя колонка «Комментарий».

Sheet Авито
A1: № | B1: Вещь на продажу | C1: 46296 | D1: Комментарий | E1: ± % | F1: 46327 | G1: Комментарий | H1: ± % | I1: 46357 | J1: Комментарий | K1: Общий комментарий
B2: ИТОГО к продаже | C2: =SUM(C3:C17) | E2: =IF(OR(N(C2)=0,N(F2)=0),"",(F2-C2)/ABS(C2)) | F2: =SUM(F3:F17) | H2: =IF(OR(N(F2)=0,N(I2)=0),"",(I2-F2)/ABS(F2)) | I2: =SUM(I3:I17)
A3: 1 | B3: Прочее c 3д принт 14к | E3: =IF(OR(N(C3)=0,N(F3)=0),"",(F3-C3)/ABS(C3)) | H3: =IF(OR(N(F3)=0,N(I3)=0),"",(I3-F3)/ABS(F3))
A4: 2 | B4: Айфон 11 (надо его восстановить) | E4: =IF(OR(N(C4)=0,N(F4)=0),"",(F4-C4)/ABS(C4)) | H4: =IF(OR(N(F4)=0,N(I4)=0),"",(I4-F4)/ABS(F4))
A5: 3 | B5: Маркер пейнтбола | E5: =IF(OR(N(C5)=0,N(F5)=0),"",(F5-C5)/ABS(C5)) | H5: =IF(OR(N(F5)=0,N(I5)=0),"",(I5-F5)/ABS(F5))
A6: 4 | B6: Ноут и клава | E6: =IF(OR(N(C6)=0,N(F6)=0),"",(F6-C6)/ABS(C6)) | H6: =IF(OR(N(F6)=0,N(I6)=0),"",(I6-F6)/ABS(F6))
A7: 5 | B7: Хоккей | E7: =IF(OR(N(C7)=0,N(F7)=0),"",(F7-C7)/ABS(C7)) | H7: =IF(OR(N(F7)=0,N(I7)=0),"",(I7-F7)/ABS(F7))
A8: 6 | B8: Moncler кеды | E8: =IF(OR(N(C8)=0,N(F8)=0),"",(F8-C8)/ABS(C8)) | H8: =IF(OR(N(F8)=0,N(I8)=0),"",(I8-F8)/ABS(F8))
A9: 7 | B9: Клюшка | E9: =IF(OR(N(C9)=0,N(F9)=0),"",(F9-C9)/ABS(C9)) | H9: =IF(OR(N(F9)=0,N(I9)=0),"",(I9-F9)/ABS(F9))
A10: 8 | E10: =IF(OR(N(C10)=0,N(F10)=0),"",(F10-C10)/ABS(C10)) | H10: =IF(OR(N(F10)=0,N(I10)=0),"",(I10-F10)/ABS(F10))
A11: 9 | E11: =IF(OR(N(C11)=0,N(F11)=0),"",(F11-C11)/ABS(C11)) | H11: =IF(OR(N(F11)=0,N(I11)=0),"",(I11-F11)/ABS(F11))
A12: 10 | E12: =IF(OR(N(C12)=0,N(F12)=0),"",(F12-C12)/ABS(C12)) | H12: =IF(OR(N(F12)=0,N(I12)=0),"",(I12-F12)/ABS(F12))
A13: 11 | E13: =IF(OR(N(C13)=0,N(F13)=0),"",(F13-C13)/ABS(C13)) | H13: =IF(OR(N(F13)=0,N(I13)=0),"",(I13-F13)/ABS(F13))
A14: 12 | E14: =IF(OR(N(C14)=0,N(F14)=0),"",(F14-C14)/ABS(C14)) | H14: =IF(OR(N(F14)=0,N(I14)=0),"",(I14-F14)/ABS(F14))
A15: 13 | E15: =IF(OR(N(C15)=0,N(F15)=0),"",(F15-C15)/ABS(C15)) | H15: =IF(OR(N(F15)=0,N(I15)=0),"",(I15-F15)/ABS(F15))
A16: 14 | E16: =IF(OR(N(C16)=0,N(F16)=0),"",(F16-C16)/ABS(C16)) | H16: =IF(OR(N(F16)=0,N(I16)=0),"",(I16-F16)/ABS(F16))
A17: 15 | E17: =IF(OR(N(C17)=0,N(F17)=0),"",(F17-C17)/ABS(C17)) | H17: =IF(OR(N(F17)=0,N(I17)=0),"",(I17-F17)/ABS(F17))
B19: Светло-жёлтые ячейки — для ввода. Серые и синие — считаются формулами, их не трогать. «± %» — изменение к прошлому месяцу (зелёный — рост, красный — падение), появляется, когда заполнены оба месяца. Итог по каждой дате попадает в «КАПИТАЛ» → «Продать на Авито». У каждого месяца своя колонка «Комментарий».
