Workbook

Sheet КАПИТАЛ
A1: № | B1: КАПИТАЛ | C1: 46296 | E1: ± % | F1: 46327 | H1: ± % | I1: 46357
C2: Кол-во / заметка | D2: Сумма, ₽ | F2: Кол-во / заметка | G2: Сумма, ₽ | I2: Кол-во / заметка | J2: Сумма, ₽
B3: ЛИЧНЫЕ (всего) | D3: =D4+D16+D30 -> 0 | E3: =IF(OR(N(D3)=0,N(G3)=0),"",(G3-D3)/ABS(D3)) | G3: =G4+G16+G30 -> 0 | H3: =IF(OR(N(G3)=0,N(J3)=0),"",(J3-G3)/ABS(G3)) | J3: =J4+J16+J30 -> 0
B4: Активы | D4: =SUM(D5:D15) -> 0 | E4: =IF(OR(N(D4)=0,N(G4)=0),"",(G4-D4)/ABS(D4)) | G4: =SUM(G5:G15) -> 0 | H4: =IF(OR(N(G4)=0,N(J4)=0),"",(J4-G4)/ABS(G4)) | J4: =SUM(J5:J15) -> 0
A5: 1 | B5: Альфа накопительный | E5: =IF(OR(N(D5)=0,N(G5)=0),"",(G5-D5)/ABS(D5)) | H5: =IF(OR(N(G5)=0,N(J5)=0),"",(J5-G5)/ABS(G5))
A6: 2 | B6: Альфа инвестиции | E6: =IF(OR(N(D6)=0,N(G6)=0),"",(G6-D6)/ABS(D6)) | H6: =IF(OR(N(G6)=0,N(J6)=0),"",(J6-G6)/ABS(G6))
A7: 3 | B7: Райф инвестиции | E7: =IF(OR(N(D7)=0,N(G7)=0),"",(G7-D7)/ABS(D7)) | H7: =IF(OR(N(G7)=0,N(J7)=0),"",(J7-G7)/ABS(G7))
A8: 4 | B8: Тинькофф инвестиции | E8: =IF(OR(N(D8)=0,N(G8)=0),"",(G8-D8)/ABS(D8)) | H8: =IF(OR(N(G8)=0,N(J8)=0),"",(J8-G8)/ABS(G8))
A9: 5 | E9: =IF(OR(N(D9)=0,N(G9)=0),"",(G9-D9)/ABS(D9)) | H9: =IF(OR(N(G9)=0,N(J9)=0),"",(J9-G9)/ABS(G9))
A10: 6 | E10: =IF(OR(N(D10)=0,N(G10)=0),"",(G10-D10)/ABS(D10)) | H10: =IF(OR(N(G10)=0,N(J10)=0),"",(J10-G10)/ABS(G10))
A11: 7 | E11: =IF(OR(N(D11)=0,N(G11)=0),"",(G11-D11)/ABS(D11)) | H11: =IF(OR(N(G11)=0,N(J11)=0),"",(J11-G11)/ABS(G11))
A12: 8 | E12: =IF(OR(N(D12)=0,N(G12)=0),"",(G12-D12)/ABS(D12)) | H12: =IF(OR(N(G12)=0,N(J12)=0),"",(J12-G12)/ABS(G12))
A13: 9 | E13: =IF(OR(N(D13)=0,N(G13)=0),"",(G13-D13)/ABS(D13)) | H13: =IF(OR(N(G13)=0,N(J13)=0),"",(J13-G13)/ABS(G13))
A14: 10 | E14: =IF(OR(N(D14)=0,N(G14)=0),"",(G14-D14)/ABS(D14)) | H14: =IF(OR(N(G14)=0,N(J14)=0),"",(J14-G14)/ABS(G14))
A15: 11 | E15: =IF(OR(N(D15)=0,N(G15)=0),"",(G15-D15)/ABS(D15)) | H15: =IF(OR(N(G15)=0,N(J15)=0),"",(J15-G15)/ABS(G15))
B16: Пассивы | D16: =SUM(D17:D29) -> 0 | E16: =IF(OR(N(D16)=0,N(G16)=0),"",(G16-D16)/ABS(D16)) | G16: =SUM(G17:G29) -> 0 | H16: =IF(OR(N(G16)=0,N(J16)=0),"",(J16-G16)/ABS(G16)) | J16: =SUM(J17:J29) -> 0
A17: 1 | B17: Альфа карта | E17: =IF(OR(N(D17)=0,N(G17)=0),"",(G17-D17)/ABS(D17)) | H17: =IF(OR(N(G17)=0,N(J17)=0),"",(J17-G17)/ABS(G17))
A18: 2 | B18: Доллары | D18: =C18*C33 -> 0 | E18: =IF(OR(N(D18)=0,N(G18)=0),"",(G18-D18)/ABS(D18)) | G18: =F18*F33 -> 0 | H18: =IF(OR(N(G18)=0,N(J18)=0),"",(J18-G18)/ABS(G18)) | J18: =I18*I33 -> 0
A19: 3 | B19: Евро | D19: =C19*C34 -> 0 | E19: =IF(OR(N(D19)=0,N(G19)=0),"",(G19-D19)/ABS(D19)) | G19: =F19*F34 -> 0 | H19: =IF(OR(N(G19)=0,N(J19)=0),"",(J19-G19)/ABS(G19)) | J19: =I19*I34 -> 0
A20: 4 | B20: Товар whoop | E20: =IF(OR(N(D20)=0,N(G20)=0),"",(G20-D20)/ABS(D20)) | H20: =IF(OR(N(G20)=0,N(J20)=0),"",(J20-G20)/ABS(G20))
A21: 5 | B21: ВТС | D21: =C21*C36 -> 0 | E21: =IF(OR(N(D21)=0,N(G21)=0),"",(G21-D21)/ABS(D21)) | G21: =F21*F36 -> 0 | H21: =IF(OR(N(G21)=0,N(J21)=0),"",(J21-G21)/ABS(G21)) | J21: =I21*I36 -> 0
A22: 6 | B22: Продать на Авито | D22: =Авито!C2 -> 0 | E22: =IF(OR(N(D22)=0,N(G22)=0),"",(G22-D22)/ABS(D22)) | G22: =Авито!E2 -> 0 | H22: =IF(OR(N(G22)=0,N(J22)=0),"",(J22-G22)/ABS(G22)) | J22: =Авито!G2 -> 0
A23: 7 | E23: =IF(OR(N(D23)=0,N(G23)=0),"",(G23-D23)/ABS(D23)) | H23: =IF(OR(N(G23)=0,N(J23)=0),"",(J23-G23)/ABS(G23))
A24: 8 | E24: =IF(OR(N(D24)=0,N(G24)=0),"",(G24-D24)/ABS(D24)) | H24: =IF(OR(N(G24)=0,N(J24)=0),"",(J24-G24)/ABS(G24))
A25: 9 | E25: =IF(OR(N(D25)=0,N(G25)=0),"",(G25-D25)/ABS(D25)) | H25: =IF(OR(N(G25)=0,N(J25)=0),"",(J25-G25)/ABS(G25))
A26: 10 | E26: =IF(OR(N(D26)=0,N(G26)=0),"",(G26-D26)/ABS(D26)) | H26: =IF(OR(N(G26)=0,N(J26)=0),"",(J26-G26)/ABS(G26))
A27: 11 | E27: =IF(OR(N(D27)=0,N(G27)=0),"",(G27-D27)/ABS(D27)) | H27: =IF(OR(N(G27)=0,N(J27)=0),"",(J27-G27)/ABS(G27))
A28: 12 | E28: =IF(OR(N(D28)=0,N(G28)=0),"",(G28-D28)/ABS(D28)) | H28: =IF(OR(N(G28)=0,N(J28)=0),"",(J28-G28)/ABS(G28))
A29: 13 | E29: =IF(OR(N(D29)=0,N(G29)=0),"",(G29-D29)/ABS(D29)) | H29: =IF(OR(N(G29)=0,N(J29)=0),"",(J29-G29)/ABS(G29))
B30: Плавающий капитал (с листа) | D30: ='Плавающий капитал'!D3 -> 0 | E30: =IF(OR(N(D30)=0,N(G30)=0),"",(G30-D30)/ABS(D30)) | G30: ='Плавающий капитал'!G3 -> 0 | H30: =IF(OR(N(G30)=0,N(J30)=0),"",(J30-G30)/ABS(G30)) | J30: ='Плавающий капитал'!J3 -> 0
B32: Курсы на дату, ₽ | C32: =C1 -> 46296 | E32: ± % | F32: =F1 -> 46327 | H32: ± % | I32: =I1 -> 46357
B33: Доллар | E33: =IF(OR(N(C33)=0,N(F33)=0),"",(F33-C33)/ABS(C33)) | H33: =IF(OR(N(F33)=0,N(I33)=0),"",(I33-F33)/ABS(F33))
B34: Евро | E34: =IF(OR(N(C34)=0,N(F34)=0),"",(F34-C34)/ABS(C34)) | H34: =IF(OR(N(F34)=0,N(I34)=0),"",(I34-F34)/ABS(F34))
B35: Бат | E35: =IF(OR(N(C35)=0,N(F35)=0),"",(F35-C35)/ABS(C35)) | H35: =IF(OR(N(F35)=0,N(I35)=0),"",(I35-F35)/ABS(F35))
B36: ВТС | E36: =IF(OR(N(C36)=0,N(F36)=0),"",(F36-C36)/ABS(C36)) | H36: =IF(OR(N(F36)=0,N(I36)=0),"",(I36-F36)/ABS(F36))
B37: ETH | E37: =IF(OR(N(C37)=0,N(F37)=0),"",(F37-C37)/ABS(C37)) | H37: =IF(OR(N(F37)=0,N(I37)=0),"",(I37-F37)/ABS(F37))
B39: Светло-жёлтые ячейки — для ввода. Серые и синие — считаются формулами, их не трогать. «± %» — изменение к прошлому месяцу (зелёный — рост, красный — падение), появляется, когда заполнены оба месяца. «Продать на Авито» и «Плавающий капитал» подтягиваются со своих листов. Доллары/Евро/ВТС = кол-во × курс.

Sheet Плавающий капитал
A1: № | B1: ПЛАВАЮЩИЙ КАПИТАЛ | C1: 46296 | E1: ± % | F1: 46327 | H1: ± % | I1: 46357
C2: Кол-во / заметка | D2: Сумма, ₽ | F2: Кол-во / заметка | G2: Сумма, ₽ | I2: Кол-во / заметка | J2: Сумма, ₽
B3: Плавающий капитал (всего) | D3: =D4 -> 0 | E3: =IF(OR(N(D3)=0,N(G3)=0),"",(G3-D3)/ABS(D3)) | G3: =G4 -> 0 | H3: =IF(OR(N(G3)=0,N(J3)=0),"",(J3-G3)/ABS(G3)) | J3: =J4 -> 0
B4: Активы | D4: =SUM(D5:D12) -> 0 | E4: =IF(OR(N(D4)=0,N(G4)=0),"",(G4-D4)/ABS(D4)) | G4: =SUM(G5:G12) -> 0 | H4: =IF(OR(N(G4)=0,N(J4)=0),"",(J4-G4)/ABS(G4)) | J4: =SUM(J5:J12) -> 0
A5: 1 | E5: =IF(OR(N(D5)=0,N(G5)=0),"",(G5-D5)/ABS(D5)) | H5: =IF(OR(N(G5)=0,N(J5)=0),"",(J5-G5)/ABS(G5))
A6: 2 | E6: =IF(OR(N(D6)=0,N(G6)=0),"",(G6-D6)/ABS(D6)) | H6: =IF(OR(N(G6)=0,N(J6)=0),"",(J6-G6)/ABS(G6))
A7: 3 | E7: =IF(OR(N(D7)=0,N(G7)=0),"",(G7-D7)/ABS(D7)) | H7: =IF(OR(N(G7)=0,N(J7)=0),"",(J7-G7)/ABS(G7))
A8: 4 | E8: =IF(OR(N(D8)=0,N(G8)=0),"",(G8-D8)/ABS(D8)) | H8: =IF(OR(N(G8)=0,N(J8)=0),"",(J8-G8)/ABS(G8))
A9: 5 | E9: =IF(OR(N(D9)=0,N(G9)=0),"",(G9-D9)/ABS(D9)) | H9: =IF(OR(N(G9)=0,N(J9)=0),"",(J9-G9)/ABS(G9))
A10: 6 | E10: =IF(OR(N(D10)=0,N(G10)=0),"",(G10-D10)/ABS(D10)) | H10: =IF(OR(N(G10)=0,N(J10)=0),"",(J10-G10)/ABS(G10))
A11: 7 | E11: =IF(OR(N(D11)=0,N(G11)=0),"",(G11-D11)/ABS(D11)) | H11: =IF(OR(N(G11)=0,N(J11)=0),"",(J11-G11)/ABS(G11))
A12: 8 | E12: =IF(OR(N(D12)=0,N(G12)=0),"",(G12-D12)/ABS(D12)) | H12: =IF(OR(N(G12)=0,N(J12)=0),"",(J12-G12)/ABS(G12))
B14: Светло-жёлтые ячейки — для ввода. Серые и синие — считаются формулами, их не трогать. «± %» — изменение к прошлому месяцу (зелёный — рост, красный — падение), появляется, когда заполнены оба месяца. Названия статей вписывай сам в колонку B. Итог попадает в «КАПИТАЛ».

Sheet Доходы Расходы
A1: № | B1: Статья | C1: 46296 | D1: ± % | E1: 46327 | F1: ± % | G1: 46357 | H1: Итого за период
B2: Доходы — итого за месяц | C2: =SUM(C3:C15) -> 0 | D2: =IF(OR(N(C2)=0,N(E2)=0),"",(E2-C2)/ABS(C2)) | E2: =SUM(E3:E15) -> 0 | F2: =IF(OR(N(E2)=0,N(G2)=0),"",(G2-E2)/ABS(E2)) | G2: =SUM(G3:G15) -> 0 | H2: =SUM(C2,E2,G2) -> 0
A3: 1 | B3: Карманные деньги | D3: =IF(OR(N(C3)=0,N(E3)=0),"",(E3-C3)/ABS(C3)) | F3: =IF(OR(N(E3)=0,N(G3)=0),"",(G3-E3)/ABS(E3)) | H3: =SUM(C3,E3,G3) -> 0
A4: 2 | B4: Аванс на расходы | D4: =IF(OR(N(C4)=0,N(E4)=0),"",(E4-C4)/ABS(C4)) | F4: =IF(OR(N(E4)=0,N(G4)=0),"",(G4-E4)/ABS(E4)) | H4: =SUM(C4,E4,G4) -> 0
A5: 3 | B5: Авито | D5: =IF(OR(N(C5)=0,N(E5)=0),"",(E5-C5)/ABS(C5)) | F5: =IF(OR(N(E5)=0,N(G5)=0),"",(G5-E5)/ABS(E5)) | H5: =SUM(C5,E5,G5) -> 0
A6: 4 | B6: Подарки | D6: =IF(OR(N(C6)=0,N(E6)=0),"",(E6-C6)/ABS(C6)) | F6: =IF(OR(N(E6)=0,N(G6)=0),"",(G6-E6)/ABS(E6)) | H6: =SUM(C6,E6,G6) -> 0
A7: 5 | B7: Whoop | D7: =IF(OR(N(C7)=0,N(E7)=0),"",(E7-C7)/ABS(C7)) | F7: =IF(OR(N(E7)=0,N(G7)=0),"",(G7-E7)/ABS(E7)) | H7: =SUM(C7,E7,G7) -> 0
A8: 6 | B8: Прочие | D8: =IF(OR(N(C8)=0,N(E8)=0),"",(E8-C8)/ABS(C8)) | F8: =IF(OR(N(E8)=0,N(G8)=0),"",(G8-E8)/ABS(E8)) | H8: =SUM(C8,E8,G8) -> 0
A9: 7 | D9: =IF(OR(N(C9)=0,N(E9)=0),"",(E9-C9)/ABS(C9)) | F9: =IF(OR(N(E9)=0,N(G9)=0),"",(G9-E9)/ABS(E9)) | H9: =SUM(C9,E9,G9) -> 0
A10: 8 | D10: =IF(OR(N(C10)=0,N(E10)=0),"",(E10-C10)/ABS(C10)) | F10: =IF(OR(N(E10)=0,N(G10)=0),"",(G10-E10)/ABS(E10)) | H10: =SUM(C10,E10,G10) -> 0
A11: 9 | D11: =IF(OR(N(C11)=0,N(E11)=0),"",(E11-C11)/ABS(C11)) | F11: =IF(OR(N(E11)=0,N(G11)=0),"",(G11-E11)/ABS(E11)) | H11: =SUM(C11,E11,G11) -> 0
A12: 10 | D12: =IF(OR(N(C12)=0,N(E12)=0),"",(E12-C12)/ABS(C12)) | F12: =IF(OR(N(E12)=0,N(G12)=0),"",(G12-E12)/ABS(E12)) | H12: =SUM(C12,E12,G12) -> 0
A13: 11 | D13: =IF(OR(N(C13)=0,N(E13)=0),"",(E13-C13)/ABS(C13)) | F13: =IF(OR(N(E13)=0,N(G13)=0),"",(G13-E13)/ABS(E13)) | H13: =SUM(C13,E13,G13) -> 0
A14: 12 | D14: =IF(OR(N(C14)=0,N(E14)=0),"",(E14-C14)/ABS(C14)) | F14: =IF(OR(N(E14)=0,N(G14)=0),"",(G14-E14)/ABS(E14)) | H14: =SUM(C14,E14,G14) -> 0
A15: 13 | D15: =IF(OR(N(C15)=0,N(E15)=0),"",(E15-C15)/ABS(C15)) | F15: =IF(OR(N(E15)=0,N(G15)=0),"",(G15-E15)/ABS(E15)) | H15: =SUM(C15,E15,G15) -> 0
B16: Расходы — итого за месяц | C16: =SUM(C17:C29) -> 0 | D16: =IF(OR(N(C16)=0,N(E16)=0),"",(E16-C16)/ABS(C16)) | E16: =SUM(E17:E29) -> 0 | F16: =IF(OR(N(E16)=0,N(G16)=0),"",(G16-E16)/ABS(E16)) | G16: =SUM(G17:G29) -> 0 | H16: =SUM(C16,E16,G16) -> 0
A17: 1 | B17: Рестораны | D17: =IF(OR(N(C17)=0,N(E17)=0),"",(E17-C17)/ABS(C17)) | F17: =IF(OR(N(E17)=0,N(G17)=0),"",(G17-E17)/ABS(E17)) | H17: =SUM(C17,E17,G17) -> 0
A18: 2 | B18: Интернет покупки | D18: =IF(OR(N(C18)=0,N(E18)=0),"",(E18-C18)/ABS(C18)) | F18: =IF(OR(N(E18)=0,N(G18)=0),"",(G18-E18)/ABS(E18)) | H18: =SUM(C18,E18,G18) -> 0
A19: 3 | B19: Подарки | D19: =IF(OR(N(C19)=0,N(E19)=0),"",(E19-C19)/ABS(C19)) | F19: =IF(OR(N(E19)=0,N(G19)=0),"",(G19-E19)/ABS(E19)) | H19: =SUM(C19,E19,G19) -> 0
A20: 4 | B20: Одежда | D20: =IF(OR(N(C20)=0,N(E20)=0),"",(E20-C20)/ABS(C20)) | F20: =IF(OR(N(E20)=0,N(G20)=0),"",(G20-E20)/ABS(E20)) | H20: =SUM(C20,E20,G20) -> 0
A21: 5 | B21: МТС | D21: =IF(OR(N(C21)=0,N(E21)=0),"",(E21-C21)/ABS(C21)) | F21: =IF(OR(N(E21)=0,N(G21)=0),"",(G21-E21)/ABS(E21)) | H21: =SUM(C21,E21,G21) -> 0
A22: 6 | B22: Прочие | D22: =IF(OR(N(C22)=0,N(E22)=0),"",(E22-C22)/ABS(C22)) | F22: =IF(OR(N(E22)=0,N(G22)=0),"",(G22-E22)/ABS(E22)) | H22: =SUM(C22,E22,G22) -> 0
A23: 7 | B23: Курс | D23: =IF(OR(N(C23)=0,N(E23)=0),"",(E23-C23)/ABS(C23)) | F23: =IF(OR(N(E23)=0,N(G23)=0),"",(G23-E23)/ABS(E23)) | H23: =SUM(C23,E23,G23) -> 0
A24: 8 | D24: =IF(OR(N(C24)=0,N(E24)=0),"",(E24-C24)/ABS(C24)) | F24: =IF(OR(N(E24)=0,N(G24)=0),"",(G24-E24)/ABS(E24)) | H24: =SUM(C24,E24,G24) -> 0
A25: 9 | D25: =IF(OR(N(C25)=0,N(E25)=0),"",(E25-C25)/ABS(C25)) | F25: =IF(OR(N(E25)=0,N(G25)=0),"",(G25-E25)/ABS(E25)) | H25: =SUM(C25,E25,G25) -> 0
A26: 10 | D26: =IF(OR(N(C26)=0,N(E26)=0),"",(E26-C26)/ABS(C26)) | F26: =IF(OR(N(E26)=0,N(G26)=0),"",(G26-E26)/ABS(E26)) | H26: =SUM(C26,E26,G26) -> 0
A27: 11 | D27: =IF(OR(N(C27)=0,N(E27)=0),"",(E27-C27)/ABS(C27)) | F27: =IF(OR(N(E27)=0,N(G27)=0),"",(G27-E27)/ABS(E27)) | H27: =SUM(C27,E27,G27) -> 0
A28: 12 | D28: =IF(OR(N(C28)=0,N(E28)=0),"",(E28-C28)/ABS(C28)) | F28: =IF(OR(N(E28)=0,N(G28)=0),"",(G28-E28)/ABS(E28)) | H28: =SUM(C28,E28,G28) -> 0
A29: 13 | D29: =IF(OR(N(C29)=0,N(E29)=0),"",(E29-C29)/ABS(C29)) | F29: =IF(OR(N(E29)=0,N(G29)=0),"",(G29-E29)/ABS(E29)) | H29: =SUM(C29,E29,G29) -> 0
B30: Расходы 11 — итого за месяц | C30: =SUM(C31:C40) -> 0 | D30: =IF(OR(N(C30)=0,N(E30)=0),"",(E30-C30)/ABS(C30)) | E30: =SUM(E31:E40) -> 0 | F30: =IF(OR(N(E30)=0,N(G30)=0),"",(G30-E30)/ABS(E30)) | G30: =SUM(G31:G40) -> 0 | H30: =SUM(C30,E30,G30) -> 0
A31: 1 | D31: =IF(OR(N(C31)=0,N(E31)=0),"",(E31-C31)/ABS(C31)) | F31: =IF(OR(N(E31)=0,N(G31)=0),"",(G31-E31)/ABS(E31)) | H31: =SUM(C31,E31,G31) -> 0
A32: 2 | D32: =IF(OR(N(C32)=0,N(E32)=0),"",(E32-C32)/ABS(C32)) | F32: =IF(OR(N(E32)=0,N(G32)=0),"",(G32-E32)/ABS(E32)) | H32: =SUM(C32,E32,G32) -> 0
A33: 3 | D33: =IF(OR(N(C33)=0,N(E33)=0),"",(E33-C33)/ABS(C33)) | F33: =IF(OR(N(E33)=0,N(G33)=0),"",(G33-E33)/ABS(E33)) | H33: =SUM(C33,E33,G33) -> 0
A34: 4 | D34: =IF(OR(N(C34)=0,N(E34)=0),"",(E34-C34)/ABS(C34)) | F34: =IF(OR(N(E34)=0,N(G34)=0),"",(G34-E34)/ABS(E34)) | H34: =SUM(C34,E34,G34) -> 0
A35: 5 | D35: =IF(OR(N(C35)=0,N(E35)=0),"",(E35-C35)/ABS(C35)) | F35: =IF(OR(N(E35)=0,N(G35)=0),"",(G35-E35)/ABS(E35)) | H35: =SUM(C35,E35,G35) -> 0
A36: 6 | D36: =IF(OR(N(C36)=0,N(E36)=0),"",(E36-C36)/ABS(C36)) | F36: =IF(OR(N(E36)=0,N(G36)=0),"",(G36-E36)/ABS(E36)) | H36: =SUM(C36,E36,G36) -> 0
A37: 7 | D37: =IF(OR(N(C37)=0,N(E37)=0),"",(E37-C37)/ABS(C37)) | F37: =IF(OR(N(E37)=0,N(G37)=0),"",(G37-E37)/ABS(E37)) | H37: =SUM(C37,E37,G37) -> 0
A38: 8 | D38: =IF(OR(N(C38)=0,N(E38)=0),"",(E38-C38)/ABS(C38)) | F38: =IF(OR(N(E38)=0,N(G38)=0),"",(G38-E38)/ABS(E38)) | H38: =SUM(C38,E38,G38) -> 0
A39: 9 | D39: =IF(OR(N(C39)=0,N(E39)=0),"",(E39-C39)/ABS(C39)) | F39: =IF(OR(N(E39)=0,N(G39)=0),"",(G39-E39)/ABS(E39)) | H39: =SUM(C39,E39,G39) -> 0
A40: 10 | D40: =IF(OR(N(C40)=0,N(E40)=0),"",(E40-C40)/ABS(C40)) | F40: =IF(OR(N(E40)=0,N(G40)=0),"",(G40-E40)/ABS(E40)) | H40: =SUM(C40,E40,G40) -> 0
...

Sheet Долг
A1: № | B1: Статья | C1: 46296 | D1: ± % | E1: 46327 | F1: ± % | G1: 46357 | H1: Итого за период
B2: Долг — итого за месяц | C2: =SUM(C3:C15) -> 0 | D2: =IF(OR(N(C2)=0,N(E2)=0),"",(E2-C2)/ABS(C2)) | E2: =SUM(E3:E15) -> 0 | F2: =IF(OR(N(E2)=0,N(G2)=0),"",(G2-E2)/ABS(E2)) | G2: =SUM(G3:G15) -> 0 | H2: =SUM(C2,E2,G2) -> 0
A3: 1 | B3: Кафе/доставка | D3: =IF(OR(N(C3)=0,N(E3)=0),"",(E3-C3)/ABS(C3)) | F3: =IF(OR(N(E3)=0,N(G3)=0),"",(G3-E3)/ABS(E3)) | H3: =SUM(C3,E3,G3) -> 0
A4: 2 | B4: Барбершоп | D4: =IF(OR(N(C4)=0,N(E4)=0),"",(E4-C4)/ABS(C4)) | F4: =IF(OR(N(E4)=0,N(G4)=0),"",(G4-E4)/ABS(E4)) | H4: =SUM(C4,E4,G4) -> 0
A5: 3 | B5: Такси | D5: =IF(OR(N(C5)=0,N(E5)=0),"",(E5-C5)/ABS(C5)) | F5: =IF(OR(N(E5)=0,N(G5)=0),"",(G5-E5)/ABS(E5)) | H5: =SUM(C5,E5,G5) -> 0
A6: 4 | B6: Озон/уходовые | D6: =IF(OR(N(C6)=0,N(E6)=0),"",(E6-C6)/ABS(C6)) | F6: =IF(OR(N(E6)=0,N(G6)=0),"",(G6-E6)/ABS(E6)) | H6: =SUM(C6,E6,G6) -> 0
A7: 5 | B7: Спорт | D7: =IF(OR(N(C7)=0,N(E7)=0),"",(E7-C7)/ABS(C7)) | F7: =IF(OR(N(E7)=0,N(G7)=0),"",(G7-E7)/ABS(E7)) | H7: =SUM(C7,E7,G7) -> 0
A8: 6 | B8: Одежда | D8: =IF(OR(N(C8)=0,N(E8)=0),"",(E8-C8)/ABS(C8)) | F8: =IF(OR(N(E8)=0,N(G8)=0),"",(G8-E8)/ABS(E8)) | H8: =SUM(C8,E8,G8) -> 0
A9: 7 | B9: Баня | D9: =IF(OR(N(C9)=0,N(E9)=0),"",(E9-C9)/ABS(C9)) | F9: =IF(OR(N(E9)=0,N(G9)=0),"",(G9-E9)/ABS(E9)) | H9: =SUM(C9,E9,G9) -> 0
A10: 8 | D10: =IF(OR(N(C10)=0,N(E10)=0),"",(E10-C10)/ABS(C10)) | F10: =IF(OR(N(E10)=0,N(G10)=0),"",(G10-E10)/ABS(E10)) | H10: =SUM(C10,E10,G10) -> 0
A11: 9 | D11: =IF(OR(N(C11)=0,N(E11)=0),"",(E11-C11)/ABS(C11)) | F11: =IF(OR(N(E11)=0,N(G11)=0),"",(G11-E11)/ABS(E11)) | H11: =SUM(C11,E11,G11) -> 0
A12: 10 | D12: =IF(OR(N(C12)=0,N(E12)=0),"",(E12-C12)/ABS(C12)) | F12: =IF(OR(N(E12)=0,N(G12)=0),"",(G12-E12)/ABS(E12)) | H12: =SUM(C12,E12,G12) -> 0
A13: 11 | D13: =IF(OR(N(C13)=0,N(E13)=0),"",(E13-C13)/ABS(C13)) | F13: =IF(OR(N(E13)=0,N(G13)=0),"",(G13-E13)/ABS(E13)) | H13: =SUM(C13,E13,G13) -> 0
A14: 12 | D14: =IF(OR(N(C14)=0,N(E14)=0),"",(E14-C14)/ABS(C14)) | F14: =IF(OR(N(E14)=0,N(G14)=0),"",(G14-E14)/ABS(E14)) | H14: =SUM(C14,E14,G14) -> 0
A15: 13 | D15: =IF(OR(N(C15)=0,N(E15)=0),"",(E15-C15)/ABS(C15)) | F15: =IF(OR(N(E15)=0,N(G15)=0),"",(G15-E15)/ABS(E15)) | H15: =SUM(C15,E15,G15) -> 0
B16: Дали | D16: =IF(OR(N(C16)=0,N(E16)=0),"",(E16-C16)/ABS(C16)) | F16: =IF(OR(N(E16)=0,N(G16)=0),"",(G16-E16)/ABS(E16)) | H16: =SUM(C16,E16,G16) -> 0
B17: Итого (Долг − Дали) | C17: =C2-C16 -> 0 | D17: =IF(OR(N(C17)=0,N(E17)=0),"",(E17-C17)/ABS(C17)) | E17: =E2-E16 -> 0 | F17: =IF(OR(N(E17)=0,N(G17)=0),"",(G17-E17)/ABS(E17)) | G17: =G2-G16 -> 0 | H17: =SUM(C17,E17,G17) -> 0
B19: Светло-жёлтые ячейки — для ввода. Серые и синие — считаются формулами, их не трогать. «± %» — изменение к прошлому месяцу (зелёный — рост, красный — падение), появляется, когда заполнены оба месяца.

Sheet Авито
A1: № | B1: Вещь на продажу | C1: 46296 | D1: ± % | E1: 46327 | F1: ± % | G1: 46357 | H1: Комментарий
B2: ИТОГО к продаже | C2: =SUM(C3:C17) -> 0 | D2: =IF(OR(N(C2)=0,N(E2)=0),"",(E2-C2)/ABS(C2)) | E2: =SUM(E3:E17) -> 0 | F2: =IF(OR(N(E2)=0,N(G2)=0),"",(G2-E2)/ABS(E2)) | G2: =SUM(G3:G17) -> 0
A3: 1 | B3: Прочее c 3д принт 14к | D3: =IF(OR(N(C3)=0,N(E3)=0),"",(E3-C3)/ABS(C3)) | F3: =IF(OR(N(E3)=0,N(G3)=0),"",(G3-E3)/ABS(E3))
A4: 2 | B4: Айфон 11 (надо его восстановить) | D4: =IF(OR(N(C4)=0,N(E4)=0),"",(E4-C4)/ABS(C4)) | F4: =IF(OR(N(E4)=0,N(G4)=0),"",(G4-E4)/ABS(E4))
A5: 3 | B5: Маркер пейнтбола | D5: =IF(OR(N(C5)=0,N(E5)=0),"",(E5-C5)/ABS(C5)) | F5: =IF(OR(N(E5)=0,N(G5)=0),"",(G5-E5)/ABS(E5))
A6: 4 | B6: Ноут и клава | D6: =IF(OR(N(C6)=0,N(E6)=0),"",(E6-C6)/ABS(C6)) | F6: =IF(OR(N(E6)=0,N(G6)=0),"",(G6-E6)/ABS(E6))
A7: 5 | B7: Хоккей | D7: =IF(OR(N(C7)=0,N(E7)=0),"",(E7-C7)/ABS(C7)) | F7: =IF(OR(N(E7)=0,N(G7)=0),"",(G7-E7)/ABS(E7))
A8: 6 | B8: Moncler кеды | D8: =IF(OR(N(C8)=0,N(E8)=0),"",(E8-C8)/ABS(C8)) | F8: =IF(OR(N(E8)=0,N(G8)=0),"",(G8-E8)/ABS(E8))
A9: 7 | B9: Клюшка | D9: =IF(OR(N(C9)=0,N(E9)=0),"",(E9-C9)/ABS(C9)) | F9: =IF(OR(N(E9)=0,N(G9)=0),"",(G9-E9)/ABS(E9))
A10: 8 | D10: =IF(OR(N(C10)=0,N(E10)=0),"",(E10-C10)/ABS(C10)) | F10: =IF(OR(N(E10)=0,N(G10)=0),"",(G10-E10)/ABS(E10))
A11: 9 | D11: =IF(OR(N(C11)=0,N(E11)=0),"",(E11-C11)/ABS(C11)) | F11: =IF(OR(N(E11)=0,N(G11)=0),"",(G11-E11)/ABS(E11))
A12: 10 | D12: =IF(OR(N(C12)=0,N(E12)=0),"",(E12-C12)/ABS(C12)) | F12: =IF(OR(N(E12)=0,N(G12)=0),"",(G12-E12)/ABS(E12))
A13: 11 | D13: =IF(OR(N(C13)=0,N(E13)=0),"",(E13-C13)/ABS(C13)) | F13: =IF(OR(N(E13)=0,N(G13)=0),"",(G13-E13)/ABS(E13))
A14: 12 | D14: =IF(OR(N(C14)=0,N(E14)=0),"",(E14-C14)/ABS(C14)) | F14: =IF(OR(N(E14)=0,N(G14)=0),"",(G14-E14)/ABS(E14))
A15: 13 | D15: =IF(OR(N(C15)=0,N(E15)=0),"",(E15-C15)/ABS(C15)) | F15: =IF(OR(N(E15)=0,N(G15)=0),"",(G15-E15)/ABS(E15))
A16: 14 | D16: =IF(OR(N(C16)=0,N(E16)=0),"",(E16-C16)/ABS(C16)) | F16: =IF(OR(N(E16)=0,N(G16)=0),"",(G16-E16)/ABS(E16))
A17: 15 | D17: =IF(OR(N(C17)=0,N(E17)=0),"",(E17-C17)/ABS(C17)) | F17: =IF(OR(N(E17)=0,N(G17)=0),"",(G17-E17)/ABS(E17))
B19: Светло-жёлтые ячейки — для ввода. Серые и синие — считаются формулами, их не трогать. «± %» — изменение к прошлому месяцу (зелёный — рост, красный — падение), появляется, когда заполнены оба месяца. Итог по каждой дате попадает в «КАПИТАЛ» → «Продать на Авито».
